<?xml version="1.0"?>
<robot xmlns:xacro="http://www.ros.org/wiki/xacro" name="AmrRobot">

  <xacro:property name="amr_mini_caster_wheel_radius" value="0.0432" />
  <xacro:property name="amr_mini_caster_wheel_width" value="0.032" />
  <xacro:property name="pi" value="3.14"/>

  <xacro:include filename="$(find amr_mini_description)/urdf/urdf_include/common_properties.urdf.xacro"/>

  <xacro:macro name="caster_wheel_link" params="parent locationprefix *origin">
      <joint name="${locationprefix}_caster_wheel_joint" type="continuous">
          <xacro:insert_block name="origin"/>
          <parent link="${parent}"/>
          <child link="${locationprefix}_caster_wheel_link"/>
        <axis xyz="0.0 0 1"/>
        <limit lower="-${pi}" upper="${pi}" effort="100" velocity="0.1" />
      </joint>
      <link name="${locationprefix}_caster_wheel_link">
          <visual>
            <origin xyz="0 0 0" rpy="${pi} 0 0" />
            <geometry>
              <cylinder radius="${amr_mini_caster_wheel_radius}" length="${amr_mini_caster_wheel_width}" />
            </geometry>
          </visual>
          <collision>
            <geometry>
              <cylinder radius="${amr_mini_caster_wheel_radius}" length="${amr_mini_caster_wheel_width}" />
            </geometry>
            <origin xyz="0 0 0" rpy="${pi} 0 0" />
          </collision>
          <xacro:cylinder_inertia m="1"
          r="0.05"
          l="0.05"
          o_xyz="0 0 0" o_rpy="0 0 0" />
      </link>

      <gazebo reference="${locationprefix}_caster_wheel_link">
        <material>Gazebo/Red</material>
      </gazebo> 

      <gazebo referance="${locationprefix}_caster_wheel">
        <mu1>0.01</mu1>
        <mu2>0.01</mu2>
        <slip1>1.0</slip1>
        <slip2>1.0</slip2>
        <kp>1000000.0</kp>
        <kd>100.0</kd>
        <minDepth>0.001</minDepth>
        <maxVel>1.0</maxVel>
      </gazebo> 
  </xacro:macro>
</robot>