<?xml version="1.0"?>
<robot xmlns:xacro="http://www.ros.org/wiki/xacro" name="AmrRobot">
      
    <xacro:property name="r" value="0.08045"/>
    <xacro:property name="wheel_location_x" value="-0.081046"/>
    <xacro:property name="wheel_location_y" value="0.050"/>
    <xacro:property name="wheel_location_z" value="${wheel_location_x}"/>

  <xacro:property name="pi" value="3.14"/>   
    <xacro:macro name="wheel" params="name parent reflect *origin">
        <joint name="${name}_joint" type="continuous">
            <xacro:insert_block name="origin"/>
            <parent link="${parent}"/>
            <child link="${name}"/>
            <axis xyz="0.0 1 0"/>
            <limit lower="-${pi}" upper="${pi}" effort="100" velocity="20" />
        </joint>
        <link name="${name}">
            <visual>
                <origin rpy="${pi/2} 0 ${pi/2.0*(reflect - 1)}" xyz="${reflect*wheel_location_x} ${reflect*wheel_location_y} ${wheel_location_z}"/>
                <geometry>
                <mesh filename="file://$(find amr_mini_description)/AmrMini_models/Amr_mini/meshes/wheel.STL" scale="0.001 0.001 0.001"/>
                </geometry>
            </visual>
            <collision>
                <geometry>
                    <mesh filename="file://$(find amr_mini_description)/AmrMini_models/Amr_mini/meshes/wheel.STL" scale="0.001 0.001 0.001"/>
                </geometry>
                <origin rpy="${pi/2} 0 ${pi/2.0*(reflect - 1)}" xyz="${reflect*wheel_location_x} ${reflect*wheel_location_y} ${wheel_location_z}"/>
            </collision>
            <inertial>
              <origin xyz="0 0 0" rpy="0 0 0" />
              <mass value="1.5" />
              <inertia ixx="0.0075" ixy="0.0" ixz="0.0" iyy="0.0085" iyz="0.0" izz="0.0085" />  
            </inertial>
        </link>

        <!-- <gazebo reference="${name}_wheel">
          <material>
            Gazebo/Trunk</material>
        </gazebo>

        <gazebo referance="${name}_wheel">
            <mu1>200</mu1>
            <mu2>200</mu2>
            <kp>1000000.0</kp>
            <kd>1</kd>
            <minDepth>0.001</minDepth>
            <maxVel>1.0</maxVel>
        </gazebo> -->
    
          <!-- <ros2_control name="GazeboSystem" type="system">
            <hardware>
              <plugin>gazebo_ros2_control/GazeboSystem</plugin>
            </hardware>
            <joint name="${name}_joint">
              <command_interface name="velocity">
                <param name="min">-1</param>
                <param name="max">1</param>
              </command_interface>
              <state_interface name="position"/>
              <state_interface name="velocity"/>
            </joint>
          </ros2_control>      -->

    </xacro:macro>
</robot>