<?xml version="1.0" ?>
<!-- =================================================================================== -->
<!-- |    This document was autogenerated by xacro from amr_mini.xacro                 | -->
<!-- |    EDITING THIS FILE BY HAND IS NOT RECOMMENDED                                 | -->
<!-- =================================================================================== -->
<robot name="AmrRobot">
  <!-- inertial-->
  <!-- ======================================================================= -->
  <!-- ===================== Default intertial xacro =============================


  params:
  - m
  [float]: link mass;
-->
  <!-- <xacro:macro name="default_inertial" params="mass">
    <inertial>
      <mass value="${mass}" />
      <inertia ixx="1.0" ixy="0.0" ixz="0.0" iyy="1.0" iyz="0.0" izz="1.0" />
    </inertial>
  </xacro:macro> -->
  <!-- ========================================================================-->
  <!-- ===================== Material ============================================

  RVIZ material
  RGBA definition.
-->
  <!-- 
  <material name="blue">
    <color rgba="0 0 0.8 1" />
  </material>

  <material name="white">
    <color rgba="1 1 1 1" />
  </material>

  <material name="silver">
    <color rgba="0.79 0.82 0.93 1" />
  </material>
  <material name="dark_grey">
    <color rgba="0.3 0.3 0.3 1" />
  </material>
  <material name="grey">
    <color rgba="0.5 0.5 0.5 1" />
  </material>
  <material name="light_grey">
    <color rgba="0.7 0.7 0.7 1" />
  </material>

  <material name="brown">
    <color rgba="0.5 0.5 0.0 1.0" />
  </material>
  <material name="bone">
    <color rgba="0.9 0.9 0.8 1.0" />
  </material>

  <material name="bronze">
    <color rgba="0.8 0.5 0.2 1.0" />
  </material>


  <material name="black">
    <color rgba="0 0 0 1" />
  </material>


  <material name="red">
    <color rgba="1 0 0 1" />
  </material>

  <material name="green">
    <color rgba="0 1 0 1" />
  </material>

  <material name="yellow">
    <color rgba="1 1 0 1" />
  </material>


  <material name="orange">
    <color rgba="1 0.5 0 1" />
  </material>


  <material name="purple">
    <color rgba="0.5 0 0.5 1" />
  </material>

  <material name="cyan">
    <color rgba="0 1 1 1" />
  </material>

  <material name="magenta">
    <color rgba="1 0 1 1" />
  </material> -->
  <!-- ======================================================================= -->
  <!-- ===================== Default intertial xacro =============================


  params:
  - m
  [float]: link mass;
-->
  <!-- <xacro:macro name="default_inertial" params="mass">
    <inertial>
      <mass value="${mass}" />
      <inertia ixx="1.0" ixy="0.0" ixz="0.0" iyy="1.0" iyz="0.0" izz="1.0" />
    </inertial>
  </xacro:macro> -->
  <!-- ========================================================================-->
  <!-- ===================== Material ============================================

  RVIZ material
  RGBA definition.
-->
  <!-- 
  <material name="blue">
    <color rgba="0 0 0.8 1" />
  </material>

  <material name="white">
    <color rgba="1 1 1 1" />
  </material>

  <material name="silver">
    <color rgba="0.79 0.82 0.93 1" />
  </material>
  <material name="dark_grey">
    <color rgba="0.3 0.3 0.3 1" />
  </material>
  <material name="grey">
    <color rgba="0.5 0.5 0.5 1" />
  </material>
  <material name="light_grey">
    <color rgba="0.7 0.7 0.7 1" />
  </material>

  <material name="brown">
    <color rgba="0.5 0.5 0.0 1.0" />
  </material>
  <material name="bone">
    <color rgba="0.9 0.9 0.8 1.0" />
  </material>

  <material name="bronze">
    <color rgba="0.8 0.5 0.2 1.0" />
  </material>


  <material name="black">
    <color rgba="0 0 0 1" />
  </material>


  <material name="red">
    <color rgba="1 0 0 1" />
  </material>

  <material name="green">
    <color rgba="0 1 0 1" />
  </material>

  <material name="yellow">
    <color rgba="1 1 0 1" />
  </material>


  <material name="orange">
    <color rgba="1 0.5 0 1" />
  </material>


  <material name="purple">
    <color rgba="0.5 0 0.5 1" />
  </material>

  <material name="cyan">
    <color rgba="0 1 1 1" />
  </material>

  <material name="magenta">
    <color rgba="1 0 1 1" />
  </material> -->
  <link name="base_footprint"/>
  <joint name="base_link_joint" type="fixed">
    <origin rpy="3.141592653589793 3.141592653589793 0" xyz="0 0 0.08"/>
    <parent link="base_footprint"/>
    <child link="base_link"/>
  </joint>
  <link name="base_link">
    <visual>
      <origin rpy="3.141592653589793 0 0" xyz="-0.47 0.3255 0.27"/>
      <geometry>
        <mesh filename="file:///home/mkutan/Documents/ros2_ws/install/amr_mini_description/share/amr_mini_description/AmrMini_models/Amr_mini/meshes/sase.stl" scale="0.001 0.001 0.001"/>
      </geometry>
    </visual>
    <collision>
      <geometry>
        <mesh filename="file:///home/mkutan/Documents/ros2_ws/install/amr_mini_description/share/amr_mini_description/AmrMini_models/Amr_mini/meshes/sase.stl" scale="0.001 0.001 0.001"/>
      </geometry>
      <origin rpy="3.141592653589793 0 0" xyz="-0.47 0.3255 0.27"/>
    </collision>
    <inertial>
      <origin xyz="0.0 0 0.1"/>
      <mass value="5"/>
      <inertia ixx="0.4" ixy="0" ixz="0" iyy="0.5" iyz="0" izz="0.78"/>
    </inertial>
  </link>
  <gazebo reference="base_link">
    <material>
          Gazebo/Turquoise</material>
  </gazebo>
  <joint name="right_motor_joint" type="fixed">
    <origin rpy="0 0 0" xyz="0 0.223 0"/>
    <parent link="base_link"/>
    <child link="right_motor"/>
  </joint>
  <link name="right_motor">
    <visual>
      <geometry>
        <mesh filename="file:///home/mkutan/Documents/ros2_ws/install/amr_mini_description/share/amr_mini_description/AmrMini_models/Amr_mini/meshes/motor.stl" scale="0.001 0.001 0.00065"/>
      </geometry>
      <origin rpy="1.57 0 0 " xyz="0 0.05 0"/>
    </visual>
    <collision>
      <geometry>
        <mesh filename="file:///home/mkutan/Documents/ros2_ws/install/amr_mini_description/share/amr_mini_description/AmrMini_models/Amr_mini/meshes/motor.stl" scale="0.001 0.001 0.00065"/>
      </geometry>
      <origin rpy="1.57 0 0 " xyz="0 0.05 0"/>
    </collision>
  </link>
  <gazebo reference="right_motor">
    <material>
        Gazebo/Blue</material>
  </gazebo>
  <joint name="left_motor_joint" type="fixed">
    <origin rpy="-3.141592653589793 3.141592653589793 0" xyz="0 -0.223 0"/>
    <parent link="base_link"/>
    <child link="left_motor"/>
  </joint>
  <link name="left_motor">
    <visual>
      <geometry>
        <mesh filename="file:///home/mkutan/Documents/ros2_ws/install/amr_mini_description/share/amr_mini_description/AmrMini_models/Amr_mini/meshes/motor.stl" scale="0.001 0.001 0.00065"/>
      </geometry>
      <origin rpy="1.57 0 0 " xyz="0 0.05 0"/>
    </visual>
    <collision>
      <geometry>
        <mesh filename="file:///home/mkutan/Documents/ros2_ws/install/amr_mini_description/share/amr_mini_description/AmrMini_models/Amr_mini/meshes/motor.stl" scale="0.001 0.001 0.00065"/>
      </geometry>
      <origin rpy="1.57 0 0 " xyz="0 0.05 0"/>
    </collision>
  </link>
  <gazebo reference="left_motor">
    <material>
        Gazebo/Blue</material>
  </gazebo>
  <joint name="right_wheel_joint" type="continuous">
    <origin rpy="0 0 3.141592653589793" xyz="0 0.25 0.002"/>
    <parent link="base_link"/>
    <child link="right_wheel"/>
    <axis xyz="0.0 1 0"/>
    <limit effort="100" lower="-3.141592653589793" upper="3.141592653589793" velocity="20"/>
  </joint>
  <link name="right_wheel">
    <visual>
      <origin rpy="1.5707963267948966 0 -3.141592653589793" xyz="0.081046 -0.05 -0.081046"/>
      <geometry>
        <mesh filename="file:///home/mkutan/Documents/ros2_ws/install/amr_mini_description/share/amr_mini_description/AmrMini_models/Amr_mini/meshes/wheel.STL" scale="0.001 0.001 0.001"/>
      </geometry>
    </visual>
    <collision>
      <geometry>
        <mesh filename="file:///home/mkutan/Documents/ros2_ws/install/amr_mini_description/share/amr_mini_description/AmrMini_models/Amr_mini/meshes/wheel.STL" scale="0.001 0.001 0.001"/>
      </geometry>
      <origin rpy="1.5707963267948966 0 -3.141592653589793" xyz="0.081046 -0.05 -0.081046"/>
    </collision>
    <inertial>
      <origin rpy="0 0 0" xyz="0 0 0"/>
      <mass value="1.5"/>
      <inertia ixx="0.0075" ixy="0.0" ixz="0.0" iyy="0.0085" iyz="0.0" izz="0.0085"/>
    </inertial>
  </link>
  <gazebo reference="right_wheel_wheel">
    <material>
            Gazebo/Trunk</material>
  </gazebo>
  <gazebo referance="right_wheel_wheel">
    <mu1>200</mu1>
    <mu2>200</mu2>
    <kp>1000000.0</kp>
    <kd>1</kd>
    <minDepth>0.001</minDepth>
    <maxVel>1.0</maxVel>
  </gazebo>
   --&gt;

  <!--     
          <ros2_control name="GazeboSystem" type="system">
            <hardware>
              <plugin>gazebo_ros2_control/GazeboSystem</plugin>
            </hardware>
            <joint name="${name}_joint">
              <command_interface name="velocity">
                <param name="min">-1</param>
                <param name="max">1</param>
              </command_interface>
              <state_interface name="position"/>
              <state_interface name="velocity"/>
            </joint>
          </ros2_control>      -->
  <joint name="left_wheel_joint" type="continuous">
    <origin rpy="0 0 3.141592653589793" xyz="0 -0.25 0.002"/>
    <parent link="base_link"/>
    <child link="left_wheel"/>
    <axis xyz="0.0 1 0"/>
    <limit effort="100" lower="-3.141592653589793" upper="3.141592653589793" velocity="20"/>
  </joint>
  <link name="left_wheel">
    <visual>
      <origin rpy="1.5707963267948966 0 0.0" xyz="-0.081046 0.05 -0.081046"/>
      <geometry>
        <mesh filename="file:///home/mkutan/Documents/ros2_ws/install/amr_mini_description/share/amr_mini_description/AmrMini_models/Amr_mini/meshes/wheel.STL" scale="0.001 0.001 0.001"/>
      </geometry>
    </visual>
    <collision>
      <geometry>
        <mesh filename="file:///home/mkutan/Documents/ros2_ws/install/amr_mini_description/share/amr_mini_description/AmrMini_models/Amr_mini/meshes/wheel.STL" scale="0.001 0.001 0.001"/>
      </geometry>
      <origin rpy="1.5707963267948966 0 0.0" xyz="-0.081046 0.05 -0.081046"/>
    </collision>
    <inertial>
      <origin rpy="0 0 0" xyz="0 0 0"/>
      <mass value="1.5"/>
      <inertia ixx="0.0075" ixy="0.0" ixz="0.0" iyy="0.0085" iyz="0.0" izz="0.0085"/>
    </inertial>
  </link>
  <gazebo reference="left_wheel_wheel">
    <material>
            Gazebo/Trunk</material>
  </gazebo>
  <gazebo referance="left_wheel_wheel">
    <mu1>200</mu1>
    <mu2>200</mu2>
    <kp>1000000.0</kp>
    <kd>1</kd>
    <minDepth>0.001</minDepth>
    <maxVel>1.0</maxVel>
  </gazebo>
   --&gt;

  <!--     
          <ros2_control name="GazeboSystem" type="system">
            <hardware>
              <plugin>gazebo_ros2_control/GazeboSystem</plugin>
            </hardware>
            <joint name="${name}_joint">
              <command_interface name="velocity">
                <param name="min">-1</param>
                <param name="max">1</param>
              </command_interface>
              <state_interface name="position"/>
              <state_interface name="velocity"/>
            </joint>
          </ros2_control>      -->
  <joint name="back_lidar_joint" type="continuous">
    <origin rpy="0 0 0.15707963267948966 " xyz="0.34 0.22 0.19"/>
    <parent link="base_link"/>
    <child link="back_lidar_laser_link"/>
  </joint>
  <link name="back_lidar_laser_link">
    <visual>
      <geometry>
        <mesh filename="file:///home/mkutan/Documents/ros2_ws/install/amr_mini_description/share/amr_mini_description/AmrMini_models/Amr_mini/meshes/lidar.stl" scale="0.001 0.001 0.001"/>
      </geometry>
      <origin rpy="3.141592653589793 0 -2.5132741228718345" xyz="-0.075 0.02 0"/>
    </visual>
    <collision>
      <geometry>
        <mesh filename="file:///home/mkutan/Documents/ros2_ws/install/amr_mini_description/share/amr_mini_description/AmrMini_models/Amr_mini/meshes/lidar.stl" scale="0.001 0.001 0.001"/>
      </geometry>
      <origin rpy="3.141592653589793 0 -2.5132741228718345" xyz="-0.078 0 0"/>
    </collision>
    <inertial>
      <origin rpy="0 0 0" xyz="0 0 0"/>
      <mass value="0.14"/>
      <inertia ixx="0.0075" ixy="0.0" ixz="0.0" iyy="0.0085" iyz="0.0" izz="0.0085"/>
    </inertial>
  </link>
  <gazebo reference="back_lidar_laser_link">
    <material>Gazebo/Yellow</material>
  </gazebo>
  <gazebo reference="back_lidar_laser_link">
    <sensor name="back_lidar_rplidar_sensor" type="ray">
      <pose>0 0 0 0 0 0</pose>
      <always_on>true</always_on>
      <visualize>true</visualize>
      <update_rate>2</update_rate>
      <ray>
        <scan>
          <horizontal>
            <samples>270</samples>
            <resolution>1.00000</resolution>
            <min_angle>-1.45245</min_angle>
            <max_angle>2.7159</max_angle>
          </horizontal>
        </scan>
        <range>
          <min>0.120000</min>
          <max>20</max>
          <resolution>0.015000</resolution>
        </range>
        <noise>
          <type>gaussian</type>
          <mean>0.0</mean>
          <stddev>0.01</stddev>
        </noise>
      </ray>
      <plugin filename="libgazebo_ros_ray_sensor.so" name="gazebo_ros_head_hokuyo_controller">
        <ros>
          <remapping>~/out:=back_lidar_amr_mini_laser</remapping>
        </ros>
        <output_type>sensor_msgs/LaserScan</output_type>
        <frame_name>back_lidar_laser_link</frame_name>
      </plugin>
    </sensor>
  </gazebo>
  <joint name="front_lidar_joint" type="continuous">
    <origin rpy="0 0 -3.141592653589793" xyz="-0.34 -0.22 0.19"/>
    <parent link="base_link"/>
    <child link="front_lidar_laser_link"/>
  </joint>
  <link name="front_lidar_laser_link">
    <visual>
      <geometry>
        <mesh filename="file:///home/mkutan/Documents/ros2_ws/install/amr_mini_description/share/amr_mini_description/AmrMini_models/Amr_mini/meshes/lidar.stl" scale="0.001 0.001 0.001"/>
      </geometry>
      <origin rpy="3.141592653589793 0 -2.5132741228718345" xyz="-0.075 0.02 0"/>
    </visual>
    <collision>
      <geometry>
        <mesh filename="file:///home/mkutan/Documents/ros2_ws/install/amr_mini_description/share/amr_mini_description/AmrMini_models/Amr_mini/meshes/lidar.stl" scale="0.001 0.001 0.001"/>
      </geometry>
      <origin rpy="3.141592653589793 0 -2.5132741228718345" xyz="-0.078 0 0"/>
    </collision>
    <inertial>
      <origin rpy="0 0 0" xyz="0 0 0"/>
      <mass value="0.14"/>
      <inertia ixx="0.0075" ixy="0.0" ixz="0.0" iyy="0.0085" iyz="0.0" izz="0.0085"/>
    </inertial>
  </link>
  <gazebo reference="front_lidar_laser_link">
    <material>Gazebo/Yellow</material>
  </gazebo>
  <gazebo reference="front_lidar_laser_link">
    <sensor name="front_lidar_rplidar_sensor" type="ray">
      <pose>0 0 0 0 0 0</pose>
      <always_on>true</always_on>
      <visualize>true</visualize>
      <update_rate>2</update_rate>
      <ray>
        <scan>
          <horizontal>
            <samples>270</samples>
            <resolution>1.00000</resolution>
            <min_angle>-1.45245</min_angle>
            <max_angle>2.7159</max_angle>
          </horizontal>
        </scan>
        <range>
          <min>0.120000</min>
          <max>20</max>
          <resolution>0.015000</resolution>
        </range>
        <noise>
          <type>gaussian</type>
          <mean>0.0</mean>
          <stddev>0.01</stddev>
        </noise>
      </ray>
      <plugin filename="libgazebo_ros_ray_sensor.so" name="gazebo_ros_head_hokuyo_controller">
        <ros>
          <remapping>~/out:=front_lidar_amr_mini_laser</remapping>
        </ros>
        <output_type>sensor_msgs/LaserScan</output_type>
        <frame_name>front_lidar_laser_link</frame_name>
      </plugin>
    </sensor>
  </gazebo>
  <!-- Lidar-->
  <!-- <xacro:lidar name="main_lidar" parent="base_link">
      <origin rpy="${pi} 0 0" xyz="0 0  ${lidar_z+0.165}"/>
    </xacro:lidar> -->
  <joint name="imu_joint" type="fixed">
    <origin rpy="0 0 3.141592653589793" xyz="-0.38 0 0.07"/>
    <parent link="base_link"/>
    <child link="imu"/>
  </joint>
  <link name="imu">
    <visual>
      <origin rpy="0 0 0" xyz="0  0 -0.04"/>
      <geometry>
        <mesh filename="file:///home/mkutan/Documents/ros2_ws/install/amr_mini_description/share/amr_mini_description/AmrMini_models/Amr_mini/meshes/imu.stl" scale="0.001 0.001 0.001"/>
      </geometry>
    </visual>
    <collision>
      <origin rpy="0 0 0" xyz="0  0 -0.04"/>
      <geometry>
        <mesh filename="file:///home/mkutan/Documents/ros2_ws/install/amr_mini_description/share/amr_mini_description/AmrMini_models/Amr_mini/meshes/imu.stl" scale="0.001 0.001 0.001"/>
      </geometry>
    </collision>
  </link>
  <gazebo reference="imu">
    <material>Gazebo/Yellow</material>
  </gazebo>
  <gazebo reference="imu">
    <gravity>true</gravity>
    <sensor name="imu_sensor" type="imu">
      <always_on>true</always_on>
      <update_rate>30</update_rate>
      <visualize>true</visualize>
      <plugin filename="libgazebo_ros_imu_sensor.so" name="imu_plugin">
        <ros>
          <remapping>~/out:=imu</remapping>
        </ros>
        <frame_name>imu</frame_name>
      </plugin>
    </sensor>
  </gazebo>
  <joint name="camera_joint" type="fixed">
    <origin rpy="0 0 3.141592653589793 " xyz="-0.465 0 0.284"/>
    <parent link="base_link"/>
    <child link="camera"/>
  </joint>
  <link name="camera">
    <visual>
      <origin rpy="1.57 0 1.57" xyz="0 0 0"/>
      <geometry>
        <mesh filename="file:///home/mkutan/Documents/ros2_ws/install/amr_mini_description/share/amr_mini_description/AmrMini_models/Amr_mini/meshes/camera.dae"/>
      </geometry>
    </visual>
    <collision>
      <origin rpy="1.57 0 1.57" xyz="0 0 0"/>
      <geometry>
        <mesh filename="file:///home/mkutan/Documents/ros2_ws/install/amr_mini_description/share/amr_mini_description/AmrMini_models/Amr_mini/meshes/camera.dae"/>
      </geometry>
    </collision>
    <inertial>
      <mass value="0.05"/>
      <inertia ixx="4.166666666666668e-05" ixy="0" ixz="0" iyy="4.166666666666668e-05" iyz="0" izz="6.250000000000001e-05"/>
      <origin rpy="0 0 0" xyz="0 0 0"/>
    </inertial>
  </link>
  <gazebo reference="camera">
    <sensor name="depth_camera" type="depth">
      <visualize>true</visualize>
      <update_rate>10.0</update_rate>
      <plugin filename="libgazebo_ros_camera.so" name="camera_depth_plugin">
        <ros>
          <namespace>amr_mini_description</namespace>
          <remapping>custom_camera/image_raw:=custom_camera/custom_image</remapping>
          <remapping>custom_camera/image_depth:=custom_camera/custom_image_depth</remapping>
          <remapping>custom_camera/camera_info:=custom_camera/custom_info_raw</remapping>
          <remapping>custom_camera/camera_info_depth:=custom_camera/custom_info_depth</remapping>
          <remapping>custom_camera/points:=custom_camera/custom_points</remapping>
        </ros>
        <camera_name>custom_camera</camera_name>
        <frame_name>camera</frame_name>
        <hack_baseline>0.07</hack_baseline>
        <min_depth>0.001</min_depth>
        <max_depth>300.0</max_depth>
      </plugin>
    </sensor>
  </gazebo>
  <gazebo reference="camera">
    <sensor name="rqb_camera" type="camera">
      <visualize>true</visualize>
      <update_rate>30.0</update_rate>
      <plugin filename="libgazebo_ros_camera.so" name="camera_rqb_plugin">
        <ros>
          <namespace>amr_mini_description</namespace>
          <remapping>image_raw:=custom_img</remapping>
          <remapping>camera_info:=custom_info</remapping>
        </ros>
        <camera_name>rgb_cam</camera_name>
        <frame_name>camera</frame_name>
        <hack_baseline>0.07</hack_baseline>
      </plugin>
    </sensor>
  </gazebo>
  <joint name="back_left_caster_rotation_joint" type="continuous">
    <origin rpy="3.141592653589793 3.141592653589793 0" xyz="0.37 -0.21089999999999998 0.0536"/>
    <parent link="base_link"/>
    <child link="back_left_caster_rotation_link"/>
    <axis xyz="0.0 0.0 1.0"/>
    <limit effort="100" lower="-3.141592653589793" upper="3.141592653589793" velocity="0.1"/>
    <dynamics damping="0.01" friction="0.1"/>
  </joint>
  <link name="back_left_caster_rotation_link">
    <visual>
      <origin rpy="0 0 0" xyz="0 0 0"/>
      <geometry>
        <mesh filename="file:///home/mkutan/Documents/ros2_ws/install/amr_mini_description/share/amr_mini_description/AmrMini_models/Amr_mini/meshes/caster_wheel_base.stl" scale="1 1 0.9"/>
      </geometry>
    </visual>
    <collision>
      <geometry>
        <mesh filename="file:///home/mkutan/Documents/ros2_ws/install/amr_mini_description/share/amr_mini_description/AmrMini_models/Amr_mini/meshes/caster_wheel_base.stl" scale="1 1 0.9"/>
      </geometry>
      <origin rpy="0 0 0" xyz="0 0 0"/>
    </collision>
    <inertial>
      <origin rpy="0 0 0" xyz="0 0 -0.04"/>
      <mass value="0.21"/>
      <inertia ixx="0.0002" ixy="0.0" ixz="0.0" iyy="0.0002" iyz="0.0" izz="0.0001"/>
    </inertial>
  </link>
  <gazebo reference="back_left_caster_rotation_link">
    <material>
          Gazebo/Orange</material>
  </gazebo>
  <joint name="back_left_caster_wheel_joint" type="continuous">
    <origin rpy="1.5707963267948966 0 0 " xyz="-0.038 0 -0.08800000000000001"/>
    <parent link="back_left_caster_rotation_link"/>
    <child link="back_left_caster_wheel_link"/>
    <axis xyz="0.0 0 1"/>
    <limit effort="100" lower="-3.141592653589793" upper="3.141592653589793" velocity="0.1"/>
  </joint>
  <link name="back_left_caster_wheel_link">
    <visual>
      <origin rpy="3.141592653589793 0 0" xyz="0 0 0"/>
      <geometry>
        <cylinder length="0.032" radius="0.0432"/>
      </geometry>
    </visual>
    <collision>
      <geometry>
        <cylinder length="0.032" radius="0.0432"/>
      </geometry>
      <origin rpy="3.141592653589793 0 0" xyz="0 0 0"/>
    </collision>
    <inertial>
      <mass value="1"/>
      <inertia ixx="0.0008333333333333335" ixy="0" ixz="0" iyy="0.0008333333333333335" iyz="0" izz="0.0012500000000000002"/>
      <origin rpy="0 0 0" xyz="0 0 0"/>
    </inertial>
  </link>
  <gazebo reference="back_left_caster_wheel_link">
    <material>Gazebo/Red</material>
  </gazebo>
  <gazebo referance="back_left_caster_wheel">
    <mu1>0.01</mu1>
    <mu2>0.01</mu2>
    <slip1>1.0</slip1>
    <slip2>1.0</slip2>
    <kp>1000000.0</kp>
    <kd>100.0</kd>
    <minDepth>0.001</minDepth>
    <maxVel>1.0</maxVel>
  </gazebo>
  <joint name="back_right_caster_rotation_joint" type="continuous">
    <origin rpy="3.141592653589793 3.141592653589793 0" xyz="0.37 0.21089999999999998 0.0536"/>
    <parent link="base_link"/>
    <child link="back_right_caster_rotation_link"/>
    <axis xyz="0.0 0.0 1.0"/>
    <limit effort="100" lower="-3.141592653589793" upper="3.141592653589793" velocity="0.1"/>
    <dynamics damping="0.01" friction="0.1"/>
  </joint>
  <link name="back_right_caster_rotation_link">
    <visual>
      <origin rpy="0 0 0" xyz="0 0 0"/>
      <geometry>
        <mesh filename="file:///home/mkutan/Documents/ros2_ws/install/amr_mini_description/share/amr_mini_description/AmrMini_models/Amr_mini/meshes/caster_wheel_base.stl" scale="1 1 0.9"/>
      </geometry>
    </visual>
    <collision>
      <geometry>
        <mesh filename="file:///home/mkutan/Documents/ros2_ws/install/amr_mini_description/share/amr_mini_description/AmrMini_models/Amr_mini/meshes/caster_wheel_base.stl" scale="1 1 0.9"/>
      </geometry>
      <origin rpy="0 0 0" xyz="0 0 0"/>
    </collision>
    <inertial>
      <origin rpy="0 0 0" xyz="0 0 -0.04"/>
      <mass value="0.21"/>
      <inertia ixx="0.0002" ixy="0.0" ixz="0.0" iyy="0.0002" iyz="0.0" izz="0.0001"/>
    </inertial>
  </link>
  <gazebo reference="back_right_caster_rotation_link">
    <material>
          Gazebo/Orange</material>
  </gazebo>
  <joint name="back_right_caster_wheel_joint" type="continuous">
    <origin rpy="1.5707963267948966 0 0 " xyz="-0.038 0 -0.08800000000000001"/>
    <parent link="back_right_caster_rotation_link"/>
    <child link="back_right_caster_wheel_link"/>
    <axis xyz="0.0 0 1"/>
    <limit effort="100" lower="-3.141592653589793" upper="3.141592653589793" velocity="0.1"/>
  </joint>
  <link name="back_right_caster_wheel_link">
    <visual>
      <origin rpy="3.141592653589793 0 0" xyz="0 0 0"/>
      <geometry>
        <cylinder length="0.032" radius="0.0432"/>
      </geometry>
    </visual>
    <collision>
      <geometry>
        <cylinder length="0.032" radius="0.0432"/>
      </geometry>
      <origin rpy="3.141592653589793 0 0" xyz="0 0 0"/>
    </collision>
    <inertial>
      <mass value="1"/>
      <inertia ixx="0.0008333333333333335" ixy="0" ixz="0" iyy="0.0008333333333333335" iyz="0" izz="0.0012500000000000002"/>
      <origin rpy="0 0 0" xyz="0 0 0"/>
    </inertial>
  </link>
  <gazebo reference="back_right_caster_wheel_link">
    <material>Gazebo/Red</material>
  </gazebo>
  <gazebo referance="back_right_caster_wheel">
    <mu1>0.01</mu1>
    <mu2>0.01</mu2>
    <slip1>1.0</slip1>
    <slip2>1.0</slip2>
    <kp>1000000.0</kp>
    <kd>100.0</kd>
    <minDepth>0.001</minDepth>
    <maxVel>1.0</maxVel>
  </gazebo>
  <joint name="front_right_caster_rotation_joint" type="continuous">
    <origin rpy="-3.141592653589793 3.141592653589793 0" xyz="-0.37 0.21089999999999998 0.0536"/>
    <parent link="base_link"/>
    <child link="front_right_caster_rotation_link"/>
    <axis xyz="0.0 0.0 1.0"/>
    <limit effort="100" lower="-3.141592653589793" upper="3.141592653589793" velocity="0.1"/>
    <dynamics damping="0.01" friction="0.1"/>
  </joint>
  <link name="front_right_caster_rotation_link">
    <visual>
      <origin rpy="0 0 0" xyz="0 0 0"/>
      <geometry>
        <mesh filename="file:///home/mkutan/Documents/ros2_ws/install/amr_mini_description/share/amr_mini_description/AmrMini_models/Amr_mini/meshes/caster_wheel_base.stl" scale="1 1 0.9"/>
      </geometry>
    </visual>
    <collision>
      <geometry>
        <mesh filename="file:///home/mkutan/Documents/ros2_ws/install/amr_mini_description/share/amr_mini_description/AmrMini_models/Amr_mini/meshes/caster_wheel_base.stl" scale="1 1 0.9"/>
      </geometry>
      <origin rpy="0 0 0" xyz="0 0 0"/>
    </collision>
    <inertial>
      <origin rpy="0 0 0" xyz="0 0 -0.04"/>
      <mass value="0.21"/>
      <inertia ixx="0.0002" ixy="0.0" ixz="0.0" iyy="0.0002" iyz="0.0" izz="0.0001"/>
    </inertial>
  </link>
  <gazebo reference="front_right_caster_rotation_link">
    <material>
          Gazebo/Orange</material>
  </gazebo>
  <joint name="front_right_caster_wheel_joint" type="continuous">
    <origin rpy="1.5707963267948966 0 0 " xyz="-0.038 0 -0.08800000000000001"/>
    <parent link="front_right_caster_rotation_link"/>
    <child link="front_right_caster_wheel_link"/>
    <axis xyz="0.0 0 1"/>
    <limit effort="100" lower="-3.141592653589793" upper="3.141592653589793" velocity="0.1"/>
  </joint>
  <link name="front_right_caster_wheel_link">
    <visual>
      <origin rpy="3.141592653589793 0 0" xyz="0 0 0"/>
      <geometry>
        <cylinder length="0.032" radius="0.0432"/>
      </geometry>
    </visual>
    <collision>
      <geometry>
        <cylinder length="0.032" radius="0.0432"/>
      </geometry>
      <origin rpy="3.141592653589793 0 0" xyz="0 0 0"/>
    </collision>
    <inertial>
      <mass value="1"/>
      <inertia ixx="0.0008333333333333335" ixy="0" ixz="0" iyy="0.0008333333333333335" iyz="0" izz="0.0012500000000000002"/>
      <origin rpy="0 0 0" xyz="0 0 0"/>
    </inertial>
  </link>
  <gazebo reference="front_right_caster_wheel_link">
    <material>Gazebo/Red</material>
  </gazebo>
  <gazebo referance="front_right_caster_wheel">
    <mu1>0.01</mu1>
    <mu2>0.01</mu2>
    <slip1>1.0</slip1>
    <slip2>1.0</slip2>
    <kp>1000000.0</kp>
    <kd>100.0</kd>
    <minDepth>0.001</minDepth>
    <maxVel>1.0</maxVel>
  </gazebo>
  <joint name="front_left_caster_rotation_joint" type="continuous">
    <origin rpy="3.141592653589793 3.141592653589793 0" xyz="-0.37 -0.21089999999999998 0.0536"/>
    <parent link="base_link"/>
    <child link="front_left_caster_rotation_link"/>
    <axis xyz="0.0 0.0 1.0"/>
    <limit effort="100" lower="-3.141592653589793" upper="3.141592653589793" velocity="0.1"/>
    <dynamics damping="0.01" friction="0.1"/>
  </joint>
  <link name="front_left_caster_rotation_link">
    <visual>
      <origin rpy="0 0 0" xyz="0 0 0"/>
      <geometry>
        <mesh filename="file:///home/mkutan/Documents/ros2_ws/install/amr_mini_description/share/amr_mini_description/AmrMini_models/Amr_mini/meshes/caster_wheel_base.stl" scale="1 1 0.9"/>
      </geometry>
    </visual>
    <collision>
      <geometry>
        <mesh filename="file:///home/mkutan/Documents/ros2_ws/install/amr_mini_description/share/amr_mini_description/AmrMini_models/Amr_mini/meshes/caster_wheel_base.stl" scale="1 1 0.9"/>
      </geometry>
      <origin rpy="0 0 0" xyz="0 0 0"/>
    </collision>
    <inertial>
      <origin rpy="0 0 0" xyz="0 0 -0.04"/>
      <mass value="0.21"/>
      <inertia ixx="0.0002" ixy="0.0" ixz="0.0" iyy="0.0002" iyz="0.0" izz="0.0001"/>
    </inertial>
  </link>
  <gazebo reference="front_left_caster_rotation_link">
    <material>
          Gazebo/Orange</material>
  </gazebo>
  <joint name="front_left_caster_wheel_joint" type="continuous">
    <origin rpy="1.5707963267948966 0 0 " xyz="-0.038 0 -0.08800000000000001"/>
    <parent link="front_left_caster_rotation_link"/>
    <child link="front_left_caster_wheel_link"/>
    <axis xyz="0.0 0 1"/>
    <limit effort="100" lower="-3.141592653589793" upper="3.141592653589793" velocity="0.1"/>
  </joint>
  <link name="front_left_caster_wheel_link">
    <visual>
      <origin rpy="3.141592653589793 0 0" xyz="0 0 0"/>
      <geometry>
        <cylinder length="0.032" radius="0.0432"/>
      </geometry>
    </visual>
    <collision>
      <geometry>
        <cylinder length="0.032" radius="0.0432"/>
      </geometry>
      <origin rpy="3.141592653589793 0 0" xyz="0 0 0"/>
    </collision>
    <inertial>
      <mass value="1"/>
      <inertia ixx="0.0008333333333333335" ixy="0" ixz="0" iyy="0.0008333333333333335" iyz="0" izz="0.0012500000000000002"/>
      <origin rpy="0 0 0" xyz="0 0 0"/>
    </inertial>
  </link>
  <gazebo reference="front_left_caster_wheel_link">
    <material>Gazebo/Red</material>
  </gazebo>
  <gazebo referance="front_left_caster_wheel">
    <mu1>0.01</mu1>
    <mu2>0.01</mu2>
    <slip1>1.0</slip1>
    <slip2>1.0</slip2>
    <kp>1000000.0</kp>
    <kd>100.0</kd>
    <minDepth>0.001</minDepth>
    <maxVel>1.0</maxVel>
  </gazebo>
  <gazebo>
    <plugin filename="libgazebo_ros_diff_drive.so" name="diff_drive">
      <ros>
        <namespace>amr_mini_description</namespace>
      </ros>
      <update_rate>30</update_rate>
      <left_joint>left_wheel_joint</left_joint>
      <right_joint>right_wheel_joint</right_joint>
      <wheel_diameter>0.08</wheel_diameter>
      <wheel_separation>0.21</wheel_separation>
      <max_wheel_torque>20</max_wheel_torque>
      <max_wheel_acceleration>10</max_wheel_acceleration>
      <command_topic>cmd_vel</command_topic>
      <cmd_vel_timeout>0.5</cmd_vel_timeout>
      <publish_odom>true</publish_odom>
      <publish_odom_tf>false</publish_odom_tf>
      <publish_wheel_tf>false</publish_wheel_tf>
      <odometry_topic>odom</odometry_topic>
      <odometry_frame>odom</odometry_frame>
      <robot_base_frame>base_footprint</robot_base_frame>
    </plugin>
    <plugin filename="libgazebo_ros_joint_state_publisher.so" name="basic_joint_state">
      <ros>
        <remapping>~/out:=joint_states</remapping>
      </ros>
      <update_rate>30</update_rate>
      <joint_name>left_wheel_joint</joint_name>
      <joint_name>right_wheel_joint</joint_name>
      <joint_name>back_left_caster_wheel_joint</joint_name>
      <joint_name>back_right_caster_wheel_joint</joint_name>
      <joint_name>front_right_caster_wheel_joint</joint_name>
      <joint_name>front_left_caster_wheel_joint</joint_name>
      <joint_name>back_left_caster_rotation_joint</joint_name>
      <joint_name>back_right_caster_rotation_joint</joint_name>
      <joint_name>front_right_caster_rotation_joint</joint_name>
      <joint_name>front_left_caster_rotation_joint</joint_name>
    </plugin>
  </gazebo>
</robot>
